<?xml version="1.0"?>
<robot xmlns:xacro="http://www.ros.org/wiki/xacro" >

    <xacro:include filename="inertial_macros.xacro"/>

    <material name="white">
        <color rgba="1 1 1 1" />
    </material>

    <material name="orange">
        <color rgba="1 0.3 0.1 1"/>
    </material>

    <material name="blue">
        <color rgba="0.2 0.2 1 1"/>
    </material>

    <material name="black">
        <color rgba="0 0 0 1"/>
    </material>

    <material name="red">
        <color rgba="1 0 0 1"/>
    </material>

    <!-- BASE LINK -->
    <link name="base_link"></link>

    <!-- CHASSIS LINK -->
    <joint name="chassis_joint" type="fixed">
        <parent link="base_link"/>
        <child link="chassis"/>
        <origin xyz="0 0 0"/>
    </joint>

    <link name="chassis">
        <visual>
            <origin xyz="0 0 0.075"/>
            <geometry>
                <box size="0.3 0.3 0.15"/>
            </geometry>
            <material name="white"/>
        </visual>
    </link>

    <!-- WHEELS -->
    <joint name="left_wheel_joint" type="continuous">
        <parent link="base_link"/>
        <child link="left_wheel"/>
        <origin xyz="0.1 0.175 0" rpy="-${pi/2} 0 0" />
        <axis xyz="0 0 1"/>
    </joint>

    <link name="left_wheel">
        <visual>
            <geometry>
                <cylinder radius="0.05" length="0.04"/>
            </geometry>
            <material name="blue"/>
        </visual>
    </link>

    <joint name="right_wheel_joint" type="continuous">
        <parent link="base_link"/>
        <child link="right_wheel"/>
        <origin xyz="0.1 -0.175 0" rpy="${pi/2} 0 0" />
        <axis xyz="0 0 -1"/>
    </joint>

    <link name="right_wheel">
        <visual>
            <geometry>
                <cylinder radius="0.05" length="0.04"/>
            </geometry>
            <material name="blue"/>
        </visual>
    </link>

    <!-- NEW FRONT WHEELS -->
    <joint name="front_left_wheel_joint" type="continuous">
        <parent link="base_link"/>
        <child link="front_left_wheel"/>
        <origin xyz="-0.1 0.175 0" rpy="-${pi/2} 0 0" />
        <axis xyz="0 0 1"/>
    </joint>

    <link name="front_left_wheel">
        <visual>
            <geometry>
                <cylinder radius="0.05" length="0.04"/>
            </geometry>
            <material name="blue"/>
        </visual>
    </link>

    <joint name="front_right_wheel_joint" type="continuous">
        <parent link="base_link"/>
        <child link="front_right_wheel"/>
        <origin xyz="-0.1 -0.175 0" rpy="${pi/2} 0 0" />
        <axis xyz="0 0 -1"/>
    </joint>

    <link name="front_right_wheel">
        <visual>
            <geometry>
                <cylinder radius="0.05" length="0.04"/>
            </geometry>
            <material name="blue"/>
        </visual>
    </link>

    <!-- BASKET HOLDER -->
    <link name="basket_holder">
        <visual>
            <origin xyz="0 0 0.025"/> <!-- Position ajustée pour être directement sur le châssis -->
            <geometry>
                <box size="0.3 0.3 0.05"/>
            </geometry>
            <material name="orange"/>
        </visual>
    </link>

    <joint name="basket_holder_joint" type="fixed">
        <parent link="chassis"/>
        <child link="basket_holder"/>
        <origin xyz="0 0 0.15"/> <!-- Position du panier fixée sur le châssis -->
    </joint>

    <!-- CAMERA HOLDER -->
    <link name="camera_mount">
        <visual>
            <origin xyz="0 0 0"/> <!-- La caméra sera juste au-dessus du panier -->
            <geometry>
                <box size="0.05 0.05 0.1"/>
            </geometry>
            <material name="black"/>
        </visual>
    </link>

    <joint name="camera_mount_joint" type="fixed">
        <parent link="basket_holder"/>
        <child link="camera_mount"/>
        <origin xyz="0.15 0 0.1"/> <!-- La caméra positionnée juste au-dessus du panier -->
    </joint>

    <!-- LIGHTS -->
    <link name="front_lights">
        <visual>
            <origin xyz="0 0 0"/> <!-- Lumières positionnées sous la caméra -->
            <geometry>
                <box size="0.05 0.1 0.02"/>
            </geometry>
            <material name="red"/>
        </visual>
    </link>

    <joint name="front_lights_joint" type="fixed">
        <parent link="basket_holder"/>
        <child link="front_lights"/>
        <origin xyz="0.18 0 0.01"/> <!-- Les lumières attachées au panier -->
    </joint>

</robot>
